<?xml version="1.0"?>
<robot xmlns:xacro="http://www.ros.org/wiki/xacro">

    <!-- These constants are used to simulate a  Savox SV-0235MG servo operated at
     7.4 V. servo_stall_torque is measured in N m. servo_no_load_speed is
     measured in rad/s. -->
    <!-- produces 486.1 oz-in = 3.432620346181713 n-m of torque -->
    <!-- no load speed 0.13 sec/60 deg -> (1/0.13)*60 deg/sec = 8.05536578 rad/s -->
    <xacro:property name="servo_stall_torque" value="3.432620346181713"/>
    <xacro:property name="servo_no_load_speed" value="8.05536578"/>
    <xacro:property name="PI" value="3.14"/>


    <!-- /////////////////////////////////////////////////////-->
    <xacro:macro name="cylinder_inertia_new" params ="m r h">
        <inertial>
            <mass value="${m}"/>
            <inertia ixx="${m*(3*r*r+h*h)/12}"  ixy="0.0" ixz="0.0"
                     iyy="${m*(3*r*r+h*h)/12}"  iyz= "0.0"
                     izz="${m*r*r/2}"/>
        </inertial>
    </xacro:macro>

    <xacro:macro name="cylinder_inertia" params="mass r l">
          <inertia  ixx="${mass*(3*r*r+l*l)/12}" ixy = "0" ixz = "0"
                    iyy="${mass*(3*r*r+l*l)/12}" iyz = "0"
                    izz="${mass*(r*r)/2}" />
    </xacro:macro>
    <!-- /////////////////////////////////////////////////////-->
    <xacro:macro name= "inertial_matrix" params="mass">
        <inertial>
            <mass value="${mass}"/>
            <inertia ixx="1.0" ixy="0.0"
                     iyy="1.0" iyz="0.0"
                     izz="1.0" ixz="0.0"/>
        </inertial>
    </xacro:macro>
    <!-- /////////////////////////////////////////////////////-->

    <!-- ////////////////////////////////////////////////////-->

    <!--transmission block-->

    <xacro:macro name="Transmission_block" params="joint_name">
        <transmission name="${joint_name}_trans">
            <type>transmission_interface/SimpleTransmission</type>
            <joint name="${joint_name}">
                <hardwareInterface>PositionJointInterface</hardwareInterface>
            </joint>
            <actuator name="${joint_name}_motor">
                <mechanicalReduction>1</mechanicalReduction>
            </actuator>
        </transmission>
    </xacro:macro>

    <!-- //////////////////////////////////////////////////// -->


    <xacro:macro name="link_wheel" params="name radius length mass">
        <link name="${name}">
            <inertial>
              <mass value="${mass}"/>
              <origin rpy="0 1.5707 1.5707" xyz="0 0 0"/>
              <xacro:cylinder_inertia  mass="${mass}" r="${radius}" l="${length}" />
            </inertial>
            <collision name="${name}_collision">
              <origin rpy="0 1.5707 1.5707" xyz="0 0 0"/>
              <geometry>
                <cylinder length="${length}" radius="${radius}"/>
              </geometry>
            </collision>
            <visual name="${name}_visual">
              <origin rpy="0 1.5707 1.5707" xyz="0 0 0"/>
              <geometry>
                <cylinder length="${length}" radius="${radius}"/>
              </geometry>
              <material name="black" />
            </visual>
        </link>
    </xacro:macro>

    <xacro:macro name="joint_wheel" params="name child origin_xyz">
      <joint name="${name}" type="continuous">
        <origin rpy="0 0 0" xyz="${origin_xyz}"/>
        <child link="${child}"/>
        <parent link="link_chassis"/>
        <axis rpy="0 0 0" xyz="0 1 0"/>
        <limit effort="${servo_stall_torque}" velocity="${servo_no_load_speed}"/>
        <joint_properties damping="0.0" friction="0.0"/>
      </joint>
    </xacro:macro>


    <!-- ///////////////////      Wheels      ///////////////////////   -->

    <xacro:macro name="wheel" params= "prefix suffix origin_xyz wheel_radius wheel_width wheel_mass">
        <link name= "${prefix}_${suffix}_wheel">
            <visual name="${prefix}_${suffix}_wheel_visual">
                <origin rpy= "${PI/2} 0 0" xyz= "0 0 0"/>
                <geometry><cylinder length="${wheel_width}" radius= "${wheel_radius}"/></geometry>
                <material name= "black"/>
            </visual>
            <collision name="${prefix}_${suffix}_wheel_collision">
                <origin rpy= "${PI/2} 0 0" xyz= "0 0 0"/>
                <geometry><cylinder length="${wheel_width}" radius= "${wheel_radius}"/></geometry>
            </collision>
<!--            <inertial>-->
<!--                <mass value="${mass}"/>-->
<!--                <origin rpy="0 1.5707 1.5707" xyz="0 0 0"/>-->
<!--                <xacro:cylinder_inertia  mass="${mass}" r="${radius}" l="${length}" />-->
<!--            </inertial>-->
            <xacro:cylinder_inertia_new m="${wheel_mass}" r="${wheel_radius}" h="${wheel_width}"/>
        </link>

        <link name= "${prefix}_${suffix}_wheel1">
            <visual>
                <origin rpy= "0  ${PI/2} 0" xyz= "0 0 0"/>
                <geometry><mesh filename="package://my_robot/meshes/tyre11.dae"/></geometry>
                <material name= "Black"/>
            </visual>
            <collision>
                <origin rpy= "0 ${PI/2} 0" xyz= "0 0 0"/>
                <geometry><mesh filename="package://my_robot/meshes/tyre11.dae"/></geometry>
            </collision>
            <xacro:cylinder_inertia_new m="${wheel_mass}" r="${wheel_radius}" h="${wheel_width}"/>
        </link>

        <gazebo reference ="${prefix}_${suffix}_wheel1">
            <material>Gazebo/Black</material>
            <turnGravityOff>false</turnGravityOff>
        </gazebo>

        <joint name="${prefix}_${suffix}_wheel_joint1" type= "fixed">
            <parent link="${prefix}_${suffix}_wheel"/>
            <child link= "${prefix}_${suffix}_wheel1"/>
            <origin xyz="0 0 0"  rpy="0 0 0"/>
        </joint>

<!--        <gazebo reference ="${prefix}_${suffix}_wheel">-->
<!--            <mu1 value="200.0"/>-->
<!--            <mu2 value="100.0"/>-->
<!--            <kp value="10000000.0"/>-->
<!--            <kd value= "1.0"/>-->
<!--            <material>Gazebo/Black</material>-->
<!--        </gazebo>-->

        <joint name="${prefix}_${suffix}_wheel_joint" type="continuous">
            <parent link= "link_chassis"/>
            <child link= "${prefix}_${suffix}_wheel"/>
            <origin xyz= "${origin_xyz}" rpy="0 0 0"/>
            <axis xyz="0 1 0"/>
            <limit effort= "100" velocity="100"/>
            <dynamics damping="0.0" friction="0.0"/>
        </joint>

        <transmission name="${prefix}_${suffix}_wheel_trans">
            <type>transmission_interface/SimpleTransmission</type>
            <actuator name="${prefix}_${suffix}_wheel_motor">
                <hardwareInterface>EffortJointInterface</hardwareInterface>
                <mechanicalReduction>1</mechanicalReduction>
            </actuator>
            <joint name="${prefix}_${suffix}_wheel_joint">
                <hardwareInterface>hardware_interface/VelocityJointInterface</hardwareInterface>
            </joint>
        </transmission>
    </xacro:macro>



</robot>
